Workbook

Sheet Monthly Price & Return Data
A1: Month | B1: ICICI Lombard Close | C1: ICICI Lombard Return | D1: GIC Re Close | E1: GIC Re Return | F1: SBI Life Close | G1: SBI Life Return | H1: NIFTY 50 Close | I1: NIFTY 50 Return
A2: 43009 | B2: 677 | D2: 430.98 | F2: 662.1 | H2: 10335.3
A3: 43040 | B3: 714.35 | C3: =B3/B2-1 -> 0.055169867 | D3: 401.63 | E3: =D3/D2-1 -> -0.068100608 | F3: 654.9 | G3: =F3/F2-1 -> -0.01087449 | H3: 10226.55 | I3: =H3/H2-1 -> -0.010522191
A4: 43070 | B4: 775.5 | C4: =B4/B3-1 -> 0.085602296 | D4: 376.85 | E4: =D4/D3-1 -> -0.061698578 | F4: 695.35 | G4: =F4/F3-1 -> 0.061765155 | H4: 10530.7 | I4: =H4/H3-1 -> 0.029741213
A5: 43101 | B5: 786.9 | C5: =B5/B4-1 -> 0.014700193 | D5: 378.33 | E5: =D5/D4-1 -> 0.003927292 | F5: 660.65 | G5: =F5/F4-1 -> -0.049902927 | H5: 11027.7 | I5: =H5/H4-1 -> 0.047195343
A6: 43132 | B6: 794.8 | C6: =B6/B5-1 -> 0.010039395 | D6: 360.58 | E6: =D6/D5-1 -> -0.046916713 | F6: 694.5 | G6: =F6/F5-1 -> 0.051237418 | H6: 10492.85 | I6: =H6/H5-1 -> -0.048500594
A7: 43160 | B7: 793.85 | C7: =B7/B6-1 -> -0.0011952693 | D7: 367.05 | E7: =D7/D6-1 -> 0.017943314 | F7: 678.25 | G7: =F7/F6-1 -> -0.023398128 | H7: 10113.7 | I7: =H7/H6-1 -> -0.036134129
A8: 43191 | B8: 759.9 | C8: =B8/B7-1 -> -0.042766266 | D8: 354.58 | E8: =D8/D7-1 -> -0.033973573 | F8: 743.1 | G8: =F8/F7-1 -> 0.095613712 | H8: 10739.35 | I8: =H8/H7-1 -> 0.061861633
A9: 43221 | B9: 754.4 | C9: =B9/B8-1 -> -0.0072377944 | D9: 362.28 | E9: =D9/D8-1 -> 0.021715833 | F9: 689.8 | G9: =F9/F8-1 -> -0.071726551 | H9: 10736.15 | I9: =H9/H8-1 -> -0.00029796962
A10: 43252 | B10: 696.75 | C10: =B10/B9-1 -> -0.076418346 | D10: 366.43 | E10: =D10/D9-1 -> 0.011455228 | F10: 674.35 | G10: =F10/F9-1 -> -0.022397796 | H10: 10714.3 | I10: =H10/H9-1 -> -0.0020351802
A11: 43282 | B11: 777.7 | C11: =B11/B10-1 -> 0.11618227 | D11: 356.55 | E11: =D11/D10-1 -> -0.026962858 | F11: 686 | G11: =F11/F10-1 -> 0.017275895 | H11: 11356.5 | I11: =H11/H10-1 -> 0.059938587
A12: 43313 | B12: 795.85 | C12: =B12/B11-1 -> 0.023338048 | D12: 334 | E12: =D12/D11-1 -> -0.063244987 | F12: 672.4 | G12: =F12/F11-1 -> -0.019825073 | H12: 11680.5 | I12: =H12/H11-1 -> 0.028529917
A13: 43344 | B13: 808.35 | C13: =B13/B12-1 -> 0.015706477 | D13: 328.1 | E13: =D13/D12-1 -> -0.017664671 | F13: 511.6 | G13: =F13/F12-1 -> -0.23914337 | H13: 10930.45 | I13: =H13/H12-1 -> -0.064213861
A14: 43374 | B14: 805.45 | C14: =B14/B13-1 -> -0.0035875549 | D14: 318.15 | E14: =D14/D13-1 -> -0.03032612 | F14: 560.4 | G14: =F14/F13-1 -> 0.095387021 | H14: 10386.6 | I14: =H14/H13-1 -> -0.0497555
... A106: 46174 | B106: 1747.9 | C106: =B106/B105-1 -> -0.024718223 | D106: 363.5 | E106: =D106/D105-1 -> -0.046557377 | F106: 1765.7 | G106: =F106/F105-1 -> -0.035189334 | H106: 23382.6 | I106: =H106/H105-1 -> -0.0070134089

Sheet ICIC Lombard 
A1: Month | B1: ICICI Lombard Close | C1: Monthly Return | K1: Month | L1: NIFTY 50 Close | M1: Monthly Return | U1: RF | V1: 0.06
A2: 42979 | B2: 680.2 | K2: 42979 | L2: 9788.6 | P2: Covariance: | Q2: =COVAR(C4:C107,M4:M107)*104/103 -> 0.0019821167 | U2: RM | V2: 0.15
A3: 43009 | B3: 677 | C3: =B3/B2-1 -> -0.0047044987 | D3: Average Monthly Return | E3: =AVERAGE(C4:C107) -> 0.011310284 | K3: 43009 | L3: 10335.3 | M3: =L3/L2-1 -> 0.055850683 | P3: Variance | Q3: =VAR(M4:M107) -> 0.0023768482
A4: 43040 | B4: 714.35 | C4: =B4/B3-1 -> 0.055169867 | D4: Annualized return | E4: =E3*12 -> 0.13572341 | K4: 43040 | L4: 10226.55 | M4: =L4/L3-1 -> -0.010522191 | P4: Beta | Q4: =Q2/Q3 -> 0.83392648
A5: 43070 | B5: 775.5 | C5: =B5/B4-1 -> 0.085602296 | D5: Monthly Standard Deviation | E5: =STDEV(C4:C107) -> 0.066280758 | K5: 43070 | L5: 10530.7 | M5: =L5/L4-1 -> 0.029741213 | P5: Beta Slope | Q5: =SLOPE(C4:C107,M4:M107) -> 0.83392648
A6: 43101 | B6: 786.9 | C6: =B6/B5-1 -> 0.014700193 | D6: Annualized Standard Deviation | E6: =E5*SQRT(12) -> 0.22960328 | K6: 43101 | L6: 11027.7 | M6: =L6/L5-1 -> 0.047195343
A7: 43132 | B7: 794.8 | C7: =B7/B6-1 -> 0.010039395 | K7: 43132 | L7: 10492.85 | M7: =L7/L6-1 -> -0.048500594 | P7: Correlation | Q7: =CORREL(C4:C107,M4:M107) -> 0.61339612
A8: 43160 | B8: 793.85 | C8: =B8/B7-1 -> -0.0011952693 | K8: 43160 | L8: 10113.7 | M8: =L8/L7-1 -> -0.036134129 | P8: CAPM | Q8: =V1+Q4*(V2-V1) -> 0.13505338
A9: 43191 | B9: 759.9 | C9: =B9/B8-1 -> -0.042766266 | K9: 43191 | L9: 10739.35 | M9: =L9/L8-1 -> 0.061861633 | P9: Sharpe Ratio | Q9: =(E4-V1)/E6 -> 0.32980108
A10: 43221 | B10: 754.4 | C10: =B10/B9-1 -> -0.0072377944 | K10: 43221 | L10: 10736.15 | M10: =L10/L9-1 -> -0.00029796962 | P10: Treynor Ratio | Q10: =(E4-V1)/Q4 -> 0.09080346
A11: 43252 | B11: 696.75 | C11: =B11/B10-1 -> -0.076418346 | K11: 43252 | L11: 10714.3 | M11: =L11/L10-1 -> -0.0020351802
A12: 43282 | B12: 777.7 | C12: =B12/B11-1 -> 0.11618227 | K12: 43282 | L12: 11356.5 | M12: =L12/L11-1 -> 0.059938587
A13: 43313 | B13: 795.85 | C13: =B13/B12-1 -> 0.023338048 | K13: 43313 | L13: 11680.5 | M13: =L13/L12-1 -> 0.028529917
A14: 43344 | B14: 808.35 | C14: =B14/B13-1 -> 0.015706477 | K14: 43344 | L14: 10930.45 | M14: =L14/L13-1 -> -0.064213861
A15: 43374 | B15: 805.45 | C15: =B15/B14-1 -> -0.0035875549 | K15: 43374 | L15: 10386.6 | M15: =L15/L14-1 -> -0.0497555
A16: 43405 | B16: 833.8 | C16: =B16/B15-1 -> 0.035197716 | K16: 43405 | L16: 10876.75 | M16: =L16/L15-1 -> 0.047190611
A17: 43435 | B17: 864.45 | C17: =B17/B16-1 -> 0.036759415 | K17: 43435 | L17: 10862.55 | M17: =L17/L16-1 -> -0.001305537
A18: 43466 | B18: 880.25 | C18: =B18/B17-1 -> 0.018277517 | K18: 43466 | L18: 10830.95 | M18: =L18/L17-1 -> -0.0029090775
A19: 43497 | B19: 931.15 | C19: =B19/B18-1 -> 0.057824482 | K19: 43497 | L19: 10792.5 | M19: =L19/L18-1 -> -0.0035500118
A20: 43525 | B20: 1033.3 | C20: =B20/B19-1 -> 0.10970306 | K20: 43525 | L20: 11623.9 | M20: =L20/L19-1 -> 0.077034978
A21: 43556 | B21: 1093.35 | C21: =B21/B20-1 -> 0.058114778 | K21: 43556 | L21: 11748.15 | M21: =L21/L20-1 -> 0.010689183
A22: 43586 | B22: 1176.5 | C22: =B22/B21-1 -> 0.07605067 | K22: 43586 | L22: 11922.8 | M22: =L22/L21-1 -> 0.01486617
... A107: 46174 | B107: 1747.9 | C107: =B107/B106-1 -> -0.024718223 | K107: 46174 | L107: 23382.6 | M107: =L107/L106-1 -> -0.0070134089

Sheet SBI Life 
A1: Month | B1: SBI Life Close | C1: Monthly Return | K1: Month | L1: NIFTY 50 Close | M1: Monthly Return | U1: RF | V1: 0.06
A2: 43009 | B2: 662.1 | K2: 43009 | L2: 10335.3 | P2: Covariance | Q2: =_xlfn.COVARIANCE.S(C3:C106,M3:M106) -> 0.0022309397 | U2: RM | V2: 0.15
A3: 43040 | B3: 654.9 | C3: =B3/B2-1 -> -0.01087449 | D3: Average Monthly Return | E3: =AVERAGE(C3:C106) -> 0.012357147 | K3: 43040 | L3: 10226.55 | M3: =L3/L2-1 -> -0.010522191 | P3: Variance | Q3: =_xlfn.VAR.S(M3:M106) -> 0.0023768482
A4: 43070 | B4: 695.35 | C4: =B4/B3-1 -> 0.061765155 | D4: Annualized return | E4: =E3*12 -> 0.14828576 | K4: 43070 | L4: 10530.7 | M4: =L4/L3-1 -> 0.029741213 | P4: Beta | Q4: =Q2/Q3 -> 0.93861259
A5: 43101 | B5: 660.65 | C5: =B5/B4-1 -> -0.049902927 | D5: Monthly Standard Deviation | E5: =_xlfn.STDEV.S(C3:C106) -> 0.074865309 | K5: 43101 | L5: 11027.7 | M5: =L5/L4-1 -> 0.047195343 | P5: Beta Slope | Q5: =SLOPE(C3:C106,M3:M106) -> 0.93861259
A6: 43132 | B6: 694.5 | C6: =B6/B5-1 -> 0.051237418 | D6: Annualized Standard Deviation | E6: =E5*SQRT(12) -> 0.25934104 | K6: 43132 | L6: 10492.85 | M6: =L6/L5-1 -> -0.048500594
A7: 43160 | B7: 678.25 | C7: =B7/B6-1 -> -0.023398128 | K7: 43160 | L7: 10113.7 | M7: =L7/L6-1 -> -0.036134129 | P7: Correlation | Q7: =CORREL(C3:C106,M3:M106) -> 0.61123256
A8: 43191 | B8: 743.1 | C8: =B8/B7-1 -> 0.095613712 | K8: 43191 | L8: 10739.35 | M8: =L8/L7-1 -> 0.061861633 | P8: CAPM | Q8: =V1+Q4*(V2-V1) -> 0.14447513
A9: 43221 | B9: 689.8 | C9: =B9/B8-1 -> -0.071726551 | K9: 43221 | L9: 10736.15 | M9: =L9/L8-1 -> -0.00029796962 | P9: Sharpe Ratio | Q9: =(E4-V1)/E6 -> 0.34042341
A10: 43252 | B10: 674.35 | C10: =B10/B9-1 -> -0.022397796 | K10: 43252 | L10: 10714.3 | M10: =L10/L9-1 -> -0.0020351802 | P10: Treynor Ratio | Q10: =(E4-V1)/Q4 -> 0.094059849
A11: 43282 | B11: 686 | C11: =B11/B10-1 -> 0.017275895 | K11: 43282 | L11: 11356.5 | M11: =L11/L10-1 -> 0.059938587
A12: 43313 | B12: 672.4 | C12: =B12/B11-1 -> -0.019825073 | K12: 43313 | L12: 11680.5 | M12: =L12/L11-1 -> 0.028529917
A13: 43344 | B13: 511.6 | C13: =B13/B12-1 -> -0.23914337 | K13: 43344 | L13: 10930.45 | M13: =L13/L12-1 -> -0.064213861
A14: 43374 | B14: 560.4 | C14: =B14/B13-1 -> 0.095387021 | K14: 43374 | L14: 10386.6 | M14: =L14/L13-1 -> -0.0497555
A15: 43405 | B15: 571.4 | C15: =B15/B14-1 -> 0.019628837 | K15: 43405 | L15: 10876.75 | M15: =L15/L14-1 -> 0.047190611
A16: 43435 | B16: 597.85 | C16: =B16/B15-1 -> 0.046289814 | K16: 43435 | L16: 10862.55 | M16: =L16/L15-1 -> -0.001305537
A17: 43466 | B17: 595 | C17: =B17/B16-1 -> -0.004767082 | K17: 43466 | L17: 10830.95 | M17: =L17/L16-1 -> -0.0029090775
A18: 43497 | B18: 578.55 | C18: =B18/B17-1 -> -0.027647059 | K18: 43497 | L18: 10792.5 | M18: =L18/L17-1 -> -0.0035500118
A19: 43525 | B19: 583.4 | C19: =B19/B18-1 -> 0.0083830265 | K19: 43525 | L19: 11623.9 | M19: =L19/L18-1 -> 0.077034978
A20: 43556 | B20: 639.85 | C20: =B20/B19-1 -> 0.09676037 | K20: 43556 | L20: 11748.15 | M20: =L20/L19-1 -> 0.010689183
A21: 43586 | B21: 694.25 | C21: =B21/B20-1 -> 0.085019927 | K21: 43586 | L21: 11922.8 | M21: =L21/L20-1 -> 0.01486617
A22: 43617 | B22: 723.7 | C22: =B22/B21-1 -> 0.042419878 | K22: 43617 | L22: 11788.85 | M22: =L22/L21-1 -> -0.011234777
... A106: 46174 | B106: 1765.7 | C106: =B106/B105-1 -> -0.035189334 | K106: 46174 | L106: 23382.6 | M106: =L106/L105-1 -> -0.0070134089

Sheet GIC Re
A1: Month | B1: GIC Re Close | C1: Monthly Return | K1: Month | L1: NIFTY 50 Close | M1: Monthly Return | U1: RF | V1: 0.06
A2: 43009 | B2: 430.98 | K2: 43009 | L2: 10335.3 | P2: Covariance | Q2: =_xlfn.COVARIANCE.S(C3:C106,M3:M106) -> 0.0028634045 | U2: RM | V2: 0.15
A3: 43040 | B3: 401.63 | C3: =B3/B2-1 -> -0.068100608 | D3: Average Monthly Return | E3: =AVERAGE(C3:C106) -> 0.0062215481 | K3: 43040 | L3: 10226.55 | M3: =L3/L2-1 -> -0.010522191 | P3: Variance | Q3: =_xlfn.VAR.S(M3:M106) -> 0.0023768482
A4: 43070 | B4: 376.85 | C4: =B4/B3-1 -> -0.061698578 | D4: Annualized return | E4: =E3*12 -> 0.074658577 | K4: 43070 | L4: 10530.7 | M4: =L4/L3-1 -> 0.029741213 | P4: Beta | Q4: =Q2/Q3 -> 1.2047065
A5: 43101 | B5: 378.33 | C5: =B5/B4-1 -> 0.003927292 | D5: Monthly Standard Deviation | E5: =_xlfn.STDEV.S(C3:C106) -> 0.12803761 | K5: 43101 | L5: 11027.7 | M5: =L5/L4-1 -> 0.047195343 | P5: Beta Slope | Q5: =SLOPE(C3:C106,M3:M106) -> 1.2047065
A6: 43132 | B6: 360.58 | C6: =B6/B5-1 -> -0.046916713 | D6: Annualized Standard Deviation | E6: =E5*SQRT(12) -> 0.44353529 | K6: 43132 | L6: 10492.85 | M6: =L6/L5-1 -> -0.048500594
A7: 43160 | B7: 367.05 | C7: =B7/B6-1 -> 0.017943314 | K7: 43160 | L7: 10113.7 | M7: =L7/L6-1 -> -0.036134129 | P7: Correlation | Q7: =CORREL(C3:C106,M3:M106) -> 0.45871656
A8: 43191 | B8: 354.58 | C8: =B8/B7-1 -> -0.033973573 | K8: 43191 | L8: 10739.35 | M8: =L8/L7-1 -> 0.061861633 | P8: CAPM | Q8: =V1+Q4*(V2-V1) -> 0.16842358
A9: 43221 | B9: 362.28 | C9: =B9/B8-1 -> 0.021715833 | K9: 43221 | L9: 10736.15 | M9: =L9/L8-1 -> -0.00029796962 | P9: Sharpe Ratio | Q9: =(E4-V1)/E6 -> 0.033049404
A10: 43252 | B10: 366.43 | C10: =B10/B9-1 -> 0.011455228 | K10: 43252 | L10: 10714.3 | M10: =L10/L9-1 -> -0.0020351802 | P10: Treynor Ratio | Q10: =(E4-V1)/Q4 -> 0.012167758
A11: 43282 | B11: 356.55 | C11: =B11/B10-1 -> -0.026962858 | K11: 43282 | L11: 11356.5 | M11: =L11/L10-1 -> 0.059938587
A12: 43313 | B12: 334 | C12: =B12/B11-1 -> -0.063244987 | K12: 43313 | L12: 11680.5 | M12: =L12/L11-1 -> 0.028529917
A13: 43344 | B13: 328.1 | C13: =B13/B12-1 -> -0.017664671 | K13: 43344 | L13: 10930.45 | M13: =L13/L12-1 -> -0.064213861
A14: 43374 | B14: 318.15 | C14: =B14/B13-1 -> -0.03032612 | K14: 43374 | L14: 10386.6 | M14: =L14/L13-1 -> -0.0497555
A15: 43405 | B15: 285 | C15: =B15/B14-1 -> -0.10419613 | K15: 43405 | L15: 10876.75 | M15: =L15/L14-1 -> 0.047190611
A16: 43435 | B16: 259 | C16: =B16/B15-1 -> -0.09122807 | K16: 43435 | L16: 10862.55 | M16: =L16/L15-1 -> -0.001305537
A17: 43466 | B17: 243.4 | C17: =B17/B16-1 -> -0.06023166 | K17: 43466 | L17: 10830.95 | M17: =L17/L16-1 -> -0.0029090775
A18: 43497 | B18: 217.45 | C18: =B18/B17-1 -> -0.10661463 | K18: 43497 | L18: 10792.5 | M18: =L18/L17-1 -> -0.0035500118
A19: 43525 | B19: 241.65 | C19: =B19/B18-1 -> 0.11128995 | K19: 43525 | L19: 11623.9 | M19: =L19/L18-1 -> 0.077034978
A20: 43556 | B20: 240.2 | C20: =B20/B19-1 -> -0.0060004138 | K20: 43556 | L20: 11748.15 | M20: =L20/L19-1 -> 0.010689183
A21: 43586 | B21: 225.4 | C21: =B21/B20-1 -> -0.061615321 | K21: 43586 | L21: 11922.8 | M21: =L21/L20-1 -> 0.01486617
A22: 43617 | B22: 218.35 | C22: =B22/B21-1 -> -0.031277728 | K22: 43617 | L22: 11788.85 | M22: =L22/L21-1 -> -0.011234777
... A106: 46174 | B106: 363.5 | C106: =B106/B105-1 -> -0.046557377 | K106: 46174 | L106: 23382.6 | M106: =L106/L105-1 -> -0.0070134089

Sheet Portfolio Analysis
A1: Risk-free rate | B1: 0.06
A2: Initial investment | B2: 1000000
A4: Metric | B4: ICICI Lombard | C4: GIC Re | D4: SBI Life | E4: NIFTY 50
A5: Average Monthly Return | B5: =AVERAGE('Monthly Price & Return Data'!C3:C106) -> 0.011310284 | C5: =AVERAGE('Monthly Price & Return Data'!E3:E106) -> 0.0062215481 | D5: =AVERAGE('Monthly Price & Return Data'!G3:G106) -> 0.012357147 | E5: =AVERAGE('Monthly Price & Return Data'!I3:I106) -> 0.009094366
A6: Annualized Return | B6: =B5*12 -> 0.13572341 | C6: =C5*12 -> 0.074658577 | D6: =D5*12 -> 0.14828576 | E6: =E5*12 -> 0.10913239
A7: Monthly Standard Deviation | B7: =STDEV('Monthly Price & Return Data'!C3:C106) -> 0.066280758 | C7: =STDEV('Monthly Price & Return Data'!E3:E106) -> 0.12803761 | D7: =STDEV('Monthly Price & Return Data'!G3:G106) -> 0.074865309 | E7: =STDEV('Monthly Price & Return Data'!I3:I106) -> 0.04875293
A8: Annualized Volatility | B8: =B7*SQRT(12) -> 0.22960328 | C8: =C7*SQRT(12) -> 0.44353529 | D8: =D7*SQRT(12) -> 0.25934104 | E8: =E7*SQRT(12) -> 0.16888511
A9: Beta | B9: =SLOPE('Monthly Price & Return Data'!C3:C106,'Monthly Price & Return Data'!I3:I106) -> 0.83392648 | C9: =SLOPE('Monthly Price & Return Data'!E3:E106,'Monthly Price & Return Data'!I3:I106) -> 1.2047065 | D9: =SLOPE('Monthly Price & Return Data'!G3:G106,'Monthly Price & Return Data'!I3:I106) -> 0.93861259
A10: Correlation with NIFTY | B10: =CORREL('Monthly Price & Return Data'!C3:C106,'Monthly Price & Return Data'!I3:I106) -> 0.61339612 | C10: =CORREL('Monthly Price & Return Data'!E3:E106,'Monthly Price & Return Data'!I3:I106) -> 0.45871656 | D10: =CORREL('Monthly Price & Return Data'!G3:G106,'Monthly Price & Return Data'!I3:I106) -> 0.61123256
A11: CAPM Required Return | B11: =$B$1+B9*($E$6-$B$1) -> 0.1009728 | C11: =$B$1+C9*($E$6-$B$1) -> 0.11919011 | D11: =$B$1+D9*($E$6-$B$1) -> 0.10611628
A12: Sharpe Ratio | B12: =(B6-$B$1)/B8 -> 0.32980108 | C12: =(C6-$B$1)/C8 -> 0.033049404 | D12: =(D6-$B$1)/D8 -> 0.34042341
A13: Treynor Ratio | B13: =(B6-$B$1)/B9 -> 0.09080346 | C13: =(C6-$B$1)/C9 -> 0.012167758 | D13: =(D6-$B$1)/D9 -> 0.094059849
A16: Monthly Covariance Matrix
B17: ICICI Lombard | C17: GIC Re | D17: SBI Life
A18: ICICI Lombard | B18: =_xlfn.COVARIANCE.S('Monthly Price & Return Data'!C2:C106,'Monthly Price & Return Data'!C2:C106) -> 0.0043931389 | C18: =_xlfn.COVARIANCE.S('Monthly Price & Return Data'!C2:C106,'Monthly Price & Return Data'!E2:E106) -> 0.0032083386 | D18: =_xlfn.COVARIANCE.S('Monthly Price & Return Data'!C2:C106,'Monthly Price & Return Data'!G2:G106) -> 0.0030863163
A19: GIC Re | B19: =_xlfn.COVARIANCE.S('Monthly Price & Return Data'!E2:E106,'Monthly Price & Return Data'!C2:C106) -> 0.0032083386 | C19: =_xlfn.COVARIANCE.S('Monthly Price & Return Data'!E2:E106,'Monthly Price & Return Data'!E2:E106) -> 0.016393629 | D19: =_xlfn.COVARIANCE.S('Monthly Price & Return Data'!E2:E106,'Monthly Price & Return Data'!G2:G106) -> 0.003309707
A20: SBI Life | B20: =_xlfn.COVARIANCE.S('Monthly Price & Return Data'!G2:G106,'Monthly Price & Return Data'!C2:C106) -> 0.0030863163 | C20: =_xlfn.COVARIANCE.S('Monthly Price & Return Data'!G2:G106,'Monthly Price & Return Data'!E2:E106) -> 0.003309707 | D20: =_xlfn.COVARIANCE.S('Monthly Price & Return Data'!G2:G106,'Monthly Price & Return Data'!G2:G106) -> 0.0056048144
A22: Monthly Correlation Matrix
B23: ICICI Lombard | C23: GIC Re | D23: SBI Life
A24: ICICI Lombard | B24: =CORREL('Monthly Price & Return Data'!C2:C106,'Monthly Price & Return Data'!C2:C106) -> 1 | C24: =CORREL('Monthly Price & Return Data'!C2:C106,'Monthly Price & Return Data'!E2:E106) -> 0.37805516 | D24: =CORREL('Monthly Price & Return Data'!C2:C106,'Monthly Price & Return Data'!G2:G106) -> 0.62197416
A25: GIC Re | B25: =CORREL('Monthly Price & Return Data'!E2:E106,'Monthly Price & Return Data'!C2:C106) -> 0.37805516 | C25: =CORREL('Monthly Price & Return Data'!E2:E106,'Monthly Price & Return Data'!E2:E106) -> 1 | D25: =CORREL('Monthly Price & Return Data'!E2:E106,'Monthly Price & Return Data'!G2:G106) -> 0.34527996
A26: SBI Life | B26: =CORREL('Monthly Price & Return Data'!G2:G106,'Monthly Price & Return Data'!C2:C106) -> 0.62197416 | C26: =CORREL('Monthly Price & Return Data'!G2:G106,'Monthly Price & Return Data'!E2:E106) -> 0.34527996 | D26: =CORREL('Monthly Price & Return Data'!G2:G106,'Monthly Price & Return Data'!G2:G106) -> 1
A28: Portfolio A — Equal Weighted
A29: Stock | B29: Weight | C29: Annualized Return | D29: ₹10 Lakh Allocation
A30: ICICI Lombard | B30: =100%/3 -> 0.33333333 | C30: =$B$6 -> 0.13572341 | D30: =B30*$B$2 -> 333333.33
A31: GIC Re | B31: =100%/3 -> 0.33333333 | C31: =$C$6 -> 0.074658577 | D31: =B31*$B$2 -> 333333.33
A32: SBI Life | B32: =100%/3 -> 0.33333333 | C32: =$D$6 -> 0.14828576 | D32: =B32*$B$2 -> 333333.33
A33: Weight Total | B33: =SUM(B30:B32) -> 1
A34: Expected Return | B34: =SUMPRODUCT(B30:B32,C30:C32) -> 0.11955592
A35: Portfolio Risk | B35: =SQRT((B30^2*$B$18+B31^2*$C$19+B32^2*$D$20+2*B30*B31*$C$18+2*B30*B32*$D$18+2*B31*B32*$D$19)*12) -> 0.24657739
A36: Portfolio Beta | B36: =B30*$B$9+B31*$C$9+B32*$D$9 -> 0.99241519
A37: Sharpe Ratio | B37: =(B34-$B$1)/B35 -> 0.24153032
A38: Treynor Ratio | B38: =(B34-$B$1)/B36 -> 0.060011088
A40: Portfolio B — Maximum Sharpe (Efficient Frontier)
A41: Stock | B41: Weight | C41: Annualized Return | D41: ₹10 Lakh Allocation
A42: ICICI Lombard | B42: 0.496394 | C42: =$B$6 -> 0.13572341 | D42: =B42*$B$2 -> 496394
A43: GIC Re | B43: 0 | C43: =$C$6 -> 0.074658577 | D43: =B43*$B$2 -> 0
A44: SBI Life | B44: 0.503606 | C44: =$D$6 -> 0.14828576 | D44: =B44*$B$2 -> 503606
A45: Weight Total | B45: =SUM(B42:B44) -> 1
A46: Expected Return | B46: =SUMPRODUCT(B42:B44,C42:C44) -> 0.14204988
...

Sheet Profit & Loss Account
A1: ICICI Lombard — Profit & Loss Account
A3: Particulars (₹ crore) | B3: FY2024 | C3: FY2025 | D3: FY2026
A4: Operating profit — Fire Insurance | B4: 503.67 | C4: 783.31 | D4: 630.51
A5: Operating profit — Marine Insurance | B5: 27.21 | C5: -7.2 | D5: -73.62
A6: Operating profit — Miscellaneous Insurance | B6: 1375.02 | C6: 1490.81 | D6: 1966.84
A7: Total operating profit from insurance segments | B7: =SUM(B4:B6) -> 1905.9 | C7: =SUM(C4:C6) -> 2266.92 | D7: =SUM(D4:D6) -> 2523.73
A8: Interest, dividend & rent — gross | B8: 677.18 | C8: 804.83 | D8: 887.41
A9: Profit on sale/redemption of investments | B9: 170.92 | C9: 225.17 | D9: 275.87
A10: Loss on sale/redemption of investments | B10: -20.29 | C10: -48.45 | D10: -20.95
A11: Amortisation of investment premium/discount | B11: 17.04 | C11: 23.27 | D11: 41.17
A12: Interest income on tax refund | B12: 0 | C12: 9.57 | D12: 0
A13: Profit on sale/discard of fixed assets | B13: 0.61 | C13: 0.53 | D13: 0.43
A14: Recovery of bad debts written off | B14: 4.56 | C14: 49.29 | D14: 9.31
A15: Total Income (A) | B15: =SUM(B7:B14) -> 2755.92 | C15: =SUM(C7:C14) -> 3331.13 | D15: =SUM(D7:D14) -> 3716.97
A16: Provision for diminution in value of investments | B16: 95.82 | C16: -40.54 | D16: -11.26
A17: Provision for doubtful debts | B17: -38.68 | C17: -6.2 | D17: -22.53
A18: Total (B): provisions (rows 16–17) and other expenses | B18: 200.74 | C18: 9.82 | D18: 58.04
A19: Profit Before Tax (PBT) | B19: =B15-B18 -> 2555.18 | C19: =C15-C18 -> 3321.31 | D19: =D15-D18 -> 3658.93
A20: Current tax | B20: 660.5 | C20: 689.45 | D20: 835.18
A21: Excess/(deficit) tax provision of earlier years | B21: 3.39 | C21: 0 | D21: 0
A22: Deferred tax expense/(income) | B22: -27.3 | C22: 123.57 | D22: 51.81
A23: Total tax expense | B23: =SUM(B20:B22) -> 636.59 | C23: =SUM(C20:C22) -> 813.02 | D23: =SUM(D20:D22) -> 886.99
A24: Profit After Tax (PAT) | B24: =B19-B23 -> 1918.59 | C24: =C19-C23 -> 2508.29 | D24: =D19-D23 -> 2771.94
A25: Basic EPS (₹ per share) | B25: 39.03 | C25: 50.74 | D25: 55.74
A26: Diluted EPS (₹ per share) | B26: 38.78 | C26: 50.25 | D26: 55.24
A31: Horizontal Analysis — Year-on-Year Change (%)
A32: Particulars | B32: FY2024 | C32: FY2025 | D32: FY2026
A33: Operating profit — Fire Insurance | B33: — | C33: =IF(OR(B4=0,B4*C4<0),"n.m.",(C4-B4)/ABS(B4)) -> 0.5552048 | D33: =IF(OR(C4=0,C4*D4<0),"n.m.",(D4-C4)/ABS(C4)) -> -0.19506964
A34: Operating profit — Marine Insurance | B34: — | C34: =IF(OR(B5=0,B5*C5<0),"n.m.",(C5-B5)/ABS(B5)) -> n.m. | D34: =IF(OR(C5=0,C5*D5<0),"n.m.",(D5-C5)/ABS(C5)) -> -9.225
A35: Operating profit — Miscellaneous Insurance | B35: — | C35: =IF(OR(B6=0,B6*C6<0),"n.m.",(C6-B6)/ABS(B6)) -> 0.084209684 | D35: =IF(OR(C6=0,C6*D6<0),"n.m.",(D6-C6)/ABS(C6)) -> 0.31930964
A36: Total operating profit from insurance segments | B36: — | C36: =IF(OR(B7=0,B7*C7<0),"n.m.",(C7-B7)/ABS(B7)) -> 0.18942232 | D36: =IF(OR(C7=0,C7*D7<0),"n.m.",(D7-C7)/ABS(C7)) -> 0.11328587
A37: Interest, dividend & rent — gross | B37: — | C37: =IF(OR(B8=0,B8*C8<0),"n.m.",(C8-B8)/ABS(B8)) -> 0.18850232 | D37: =IF(OR(C8=0,C8*D8<0),"n.m.",(D8-C8)/ABS(C8)) -> 0.10260552
A38: Profit on sale/redemption of investments | B38: — | C38: =IF(OR(B9=0,B9*C9<0),"n.m.",(C9-B9)/ABS(B9)) -> 0.31739995 | D38: =IF(OR(C9=0,C9*D9<0),"n.m.",(D9-C9)/ABS(C9)) -> 0.22516321
A39: Loss on sale/redemption of investments | B39: — | C39: =IF(OR(B10=0,B10*C10<0),"n.m.",(C10-B10)/ABS(B10)) -> -1.3878758 | D39: =IF(OR(C10=0,C10*D10<0),"n.m.",(D10-C10)/ABS(C10)) -> 0.56759546
A40: Amortisation of investment premium/discount | B40: — | C40: =IF(OR(B11=0,B11*C11<0),"n.m.",(C11-B11)/ABS(B11)) -> 0.36561033 | D40: =IF(OR(C11=0,C11*D11<0),"n.m.",(D11-C11)/ABS(C11)) -> 0.76923077
A41: Interest income on tax refund | B41: — | C41: =IF(OR(B12=0,B12*C12<0),"n.m.",(C12-B12)/ABS(B12)) -> n.m. | D41: =IF(OR(C12=0,C12*D12<0),"n.m.",(D12-C12)/ABS(C12)) -> -1
A42: Profit on sale/discard of fixed assets | B42: — | C42: =IF(OR(B13=0,B13*C13<0),"n.m.",(C13-B13)/ABS(B13)) -> -0.13114754 | D42: =IF(OR(C13=0,C13*D13<0),"n.m.",(D13-C13)/ABS(C13)) -> -0.18867925
A43: Recovery of bad debts written off | B43: — | C43: =IF(OR(B14=0,B14*C14<0),"n.m.",(C14-B14)/ABS(B14)) -> 9.8092105 | D43: =IF(OR(C14=0,C14*D14<0),"n.m.",(D14-C14)/ABS(C14)) -> -0.81111787
A44: Total Income (A) | B44: — | C44: =IF(OR(B15=0,B15*C15<0),"n.m.",(C15-B15)/ABS(B15)) -> 0.20871796 | D44: =IF(OR(C15=0,C15*D15<0),"n.m.",(D15-C15)/ABS(C15)) -> 0.11582856
... A55: Diluted EPS (₹ per share) | B55: — | C55: =IF(OR(B26=0,B26*C26<0),"n.m.",(C26-B26)/ABS(B26)) -> 0.29577102 | D55: =IF(OR(C26=0,C26*D26<0),"n.m.",(D26-C26)/ABS(C26)) -> 0.099303483
...

Sheet Ratio Analysis
A1: ICICI Lombard — Financial & Insurance Ratio Analysis
B3: FY2024 | C3: FY2025 | D3: FY2026
A4: GDPI Growth (%) | B4: — | C4: =(C7-B7)/B7 -> 0.083023894 | D4: =(D7-C7)/C7 -> 0.070025715
A5: PAT Growth (%) | B5: — | C5: =(C8-B8)/B8 -> 0.30736114 | D5: =(D8-C8)/C8 -> 0.10511145
A6: Operating Profit Growth (%) | B6: — | C6: =('Profit & Loss Account'!C7-'Profit & Loss Account'!B7)/'Profit & Loss Account'!B7 -> 0.18942232 | D6: =('Profit & Loss Account'!D7-'Profit & Loss Account'!C7)/'Profit & Loss Account'!C7 -> 0.11328587
A7: Gross Direct Premium Income (₹ crore) | B7: 24776 | C7: 26833 | D7: 28712
A8: Profit After Tax (₹ crore) | B8: ='Profit & Loss Account'!B24 -> 1918.59 | C8: ='Profit & Loss Account'!C24 -> 2508.29 | D8: ='Profit & Loss Account'!D24 -> 2771.94
A9: Basic EPS (₹) | B9: ='Profit & Loss Account'!B25 -> 39.03 | C9: ='Profit & Loss Account'!C25 -> 50.74 | D9: ='Profit & Loss Account'!D25 -> 55.74
A10: Return on Average Equity (RoAE) | B10: 0.172 | C10: 0.191 | D10: 0.178
A11: Combined ratio — published headline basis | B11: 1.033 | C11: 1.028 | D11: 1.034
A12: Solvency ratio (times) | B12: 2.62 | C12: 2.69 | D12: 2.67
A13: Net incurred claims / net earned premium | B13: 0.708 | C13: 0.706 | D13: 0.711
A14: Expenses of management / GDPI | B14: 0.298 | C14: 0.308 | D14: 0.32
A15: Net commission ratio | B15: 0.17 | C15: 0.185 | D15: 0.19
A16: Operating profit ratio | B16: 0.112 | C16: 0.114 | D16: 0.11

Sheet Balance Sheet
A1: ICICI Lombard — Balance Sheet
A3: Particulars | B3: FY2024 | C3: FY2025 | D3: FY2026
A4: Share capital | B4: 492.69 | C4: 495.73 | D4: 498.49
A5: Share application money pending allotment | B5: 0.7 | C5: 0.25 | D5: 0.81
A6: Reserves and surplus | B6: 11467.09 | C6: 13807.37 | D6: 16347.42
A7: Fair value change account — shareholders' funds | B7: 244.52 | C7: 181.82 | D7: -212.83
A8: Fair value change account — policyholders' funds | B8: 745.03 | C8: 498.92 | D8: -561.64
A9: Borrowings | B9: 35 | C9: 0 | D9: 0
A10: Total sources of funds | B10: =SUM(B4:B9) -> 12985.03 | C10: =SUM(C4:C9) -> 14984.09 | D10: =SUM(D4:D9) -> 16072.25
A11: Investments — shareholders | B11: 11586.86 | C11: 13725.51 | D11: 14928.7
A12: Investments — policyholders | B12: 37320.38 | C12: 39782.26 | D12: 43492.57
A13: Loans | B13: 0 | C13: 0 | D13: 0
A14: Fixed assets | B14: 700.85 | C14: 802 | D14: 838.99
A15: Deferred tax asset (net) | B15: 292.62 | C15: 169.05 | D15: 117.24
A16: Cash and bank balances | B16: 334.58 | C16: 87.57 | D16: 986.78
A17: Advances and other assets | B17: 13073 | C17: 14453.87 | D17: 15746.66
A18: Current assets subtotal (A) | B18: =B16+B17 -> 13407.58 | C18: =C16+C17 -> 14541.44 | D18: =D16+D17 -> 16733.44
A19: Current liabilities | B19: 40235.2 | C19: 42739.46 | D19: 47585.41
A20: Provisions | B20: 10088.06 | C20: 11296.71 | D20: 12453.28
A21: Current liabilities and provisions subtotal (B) | B21: =B19+B20 -> 50323.26 | C21: =C19+C20 -> 54036.17 | D21: =D19+D20 -> 60038.69
A22: Net current assets (A − B) | B22: =B18-B21 -> -36915.68 | C22: =C18-C21 -> -39494.73 | D22: =D18-D21 -> -43305.25
A23: Total application of funds | B23: =SUM(B11:B15)+B22 -> 12985.03 | C23: =SUM(C11:C15)+C22 -> 14984.09 | D23: =SUM(D11:D15)+D22 -> 16072.25
B24: =ROUND(B10-B23,2) -> 0 | C24: =ROUND(C10-C23,2) -> 0 | D24: =ROUND(D10-D23,2) -> 0
A25: Horizontal Analysis (Trend Analysis)
A26: Particulars | B26: FY2024 | C26: FY2025 | D26: FY2026 | E26: YoY Growth (FY25) | F26: YoY Growth (FY26)
A27: Share capital | B27: =B4 -> 492.69 | C27: =C4 -> 495.73 | D27: =D4 -> 498.49 | E27: =IF(OR(B27=0,B27*C27<0),"n.m.",(C27-B27)/ABS(B27)) -> 0.0061702084 | F27: =IF(OR(C27=0,C27*D27<0),"n.m.",(D27-C27)/ABS(C27)) -> 0.0055675469
A28: Share application money pending allotment | B28: =B5 -> 0.7 | C28: =C5 -> 0.25 | D28: =D5 -> 0.81 | E28: =IF(OR(B28=0,B28*C28<0),"n.m.",(C28-B28)/ABS(B28)) -> -0.64285714 | F28: =IF(OR(C28=0,C28*D28<0),"n.m.",(D28-C28)/ABS(C28)) -> 2.24
A29: Reserves and surplus | B29: =B6 -> 11467.09 | C29: =C6 -> 13807.37 | D29: =D6 -> 16347.42 | E29: =IF(OR(B29=0,B29*C29<0),"n.m.",(C29-B29)/ABS(B29)) -> 0.20408665 | F29: =IF(OR(C29=0,C29*D29<0),"n.m.",(D29-C29)/ABS(C29)) -> 0.18396335
A30: Fair value change account — shareholders' funds | B30: =B7 -> 244.52 | C30: =C7 -> 181.82 | D30: =D7 -> -212.83 | E30: =IF(OR(B30=0,B30*C30<0),"n.m.",(C30-B30)/ABS(B30)) -> -0.25642074 | F30: =IF(OR(C30=0,C30*D30<0),"n.m.",(D30-C30)/ABS(C30)) -> n.m.
A31: Fair value change account — policyholders' funds | B31: =B8 -> 745.03 | C31: =C8 -> 498.92 | D31: =D8 -> -561.64 | E31: =IF(OR(B31=0,B31*C31<0),"n.m.",(C31-B31)/ABS(B31)) -> -0.33033569 | F31: =IF(OR(C31=0,C31*D31<0),"n.m.",(D31-C31)/ABS(C31)) -> n.m.
A32: Borrowings | B32: =B9 -> 35 | C32: =C9 -> 0 | D32: =D9 -> 0 | E32: =IF(OR(B32=0,B32*C32<0),"n.m.",(C32-B32)/ABS(B32)) -> -1 | F32: =IF(OR(C32=0,C32*D32<0),"n.m.",(D32-C32)/ABS(C32)) -> n.m.
A33: Total sources of funds | B33: =B10 -> 12985.03 | C33: =C10 -> 14984.09 | D33: =D10 -> 16072.25 | E33: =IF(OR(B33=0,B33*C33<0),"n.m.",(C33-B33)/ABS(B33)) -> 0.15395113 | F33: =IF(OR(C33=0,C33*D33<0),"n.m.",(D33-C33)/ABS(C33)) -> 0.072621027
A34: Investments — shareholders | B34: =B11 -> 11586.86 | C34: =C11 -> 13725.51 | D34: =D11 -> 14928.7 | E34: =IF(OR(B34=0,B34*C34<0),"n.m.",(C34-B34)/ABS(B34)) -> 0.18457546 | F34: =IF(OR(C34=0,C34*D34<0),"n.m.",(D34-C34)/ABS(C34)) -> 0.087660859
A35: Investments — policyholders | B35: =B12 -> 37320.38 | C35: =C12 -> 39782.26 | D35: =D12 -> 43492.57 | E35: =IF(OR(B35=0,B35*C35<0),"n.m.",(C35-B35)/ABS(B35)) -> 0.065966102 | F35: =IF(OR(C35=0,C35*D35<0),"n.m.",(D35-C35)/ABS(C35)) -> 0.09326544
A36: Fixed assets | B36: =B14 -> 700.85 | C36: =C14 -> 802 | D36: =D14 -> 838.99 | E36: =IF(OR(B36=0,B36*C36<0),"n.m.",(C36-B36)/ABS(B36)) -> 0.14432475 | F36: =IF(OR(C36=0,C36*D36<0),"n.m.",(D36-C36)/ABS(C36)) -> 0.046122195
A37: Deferred tax asset (net) | B37: =B15 -> 292.62 | C37: =C15 -> 169.05 | D37: =D15 -> 117.24 | E37: =IF(OR(B37=0,B37*C37<0),"n.m.",(C37-B37)/ABS(B37)) -> -0.42228829 | F37: =IF(OR(C37=0,C37*D37<0),"n.m.",(D37-C37)/ABS(C37)) -> -0.30647737
A38: Cash and bank balances | B38: =B16 -> 334.58 | C38: =C16 -> 87.57 | D38: =D16 -> 986.78 | E38: =IF(OR(B38=0,B38*C38<0),"n.m.",(C38-B38)/ABS(B38)) -> -0.73826887 | F38: =IF(OR(C38=0,C38*D38<0),"n.m.",(D38-C38)/ABS(C38)) -> 10.268471
A39: Advances and other assets | B39: =B17 -> 13073 | C39: =C17 -> 14453.87 | D39: =D17 -> 15746.66 | E39: =IF(OR(B39=0,B39*C39<0),"n.m.",(C39-B39)/ABS(B39)) -> 0.10562763 | F39: =IF(OR(C39=0,C39*D39<0),"n.m.",(D39-C39)/ABS(C39)) -> 0.089442481
A40: Current assets subtotal (A) | B40: =B18 -> 13407.58 | C40: =C18 -> 14541.44 | D40: =D18 -> 16733.44 | E40: =IF(OR(B40=0,B40*C40<0),"n.m.",(C40-B40)/ABS(B40)) -> 0.08456858 | F40: =IF(OR(C40=0,C40*D40<0),"n.m.",(D40-C40)/ABS(C40)) -> 0.1507416
A41: Current liabilities | B41: =B19 -> 40235.2 | C41: =C19 -> 42739.46 | D41: =D19 -> 47585.41 | E41: =IF(OR(B41=0,B41*C41<0),"n.m.",(C41-B41)/ABS(B41)) -> 0.062240526 | F41: =IF(OR(C41=0,C41*D41<0),"n.m.",(D41-C41)/ABS(C41)) -> 0.11338351
...

Sheet Cash Flow Summary
A1: ICICI Lombard — Cash Flow Summary
A3: Particulars | B3: FY2024 | C3: FY2025 | D3: FY2026
A4: Net cash flow from operating activities | B4: 2406.7742 | C4: 1147.3 | D4: 2621.97
A5: Net cash flow from investing activities | B5: -1920.736 | C5: -1137.26 | D5: -1732.72
A6: Net cash flow from financing activities | B6: -354.5906 | C6: -257.05 | D6: -335.54
A7: Net increase/(decrease) in cash equivalents | B7: =SUM(B4:B6) -> 131.4476 | C7: =SUM(C4:C6) -> -247.01 | D7: =SUM(D4:D6) -> 553.71
A8: Cash & cash equivalents at beginning of year | B8: 203.1293 | C8: =B9 -> 334.5769 | D8: 86.62
A9: Cash & cash equivalents at end of year | B9: =SUM(B7:B8) -> 334.5769 | C9: =SUM(C7:C8) -> 87.5669 | D9: =SUM(D7:D8) -> 640.33

Sheet PIOTROSKI-SCORE
A1: ICICI LOMBARD — PIOTROSKI-SCORE
A2: Metric (₹ crore unless stated) | B2: FY2024 | C2: FY2025 | D2: FY2026
A3: PAT | B3: ='Profit & Loss Account'!B24 -> 1918.59 | C3: ='Profit & Loss Account'!C24 -> 2508.29 | D3: ='Profit & Loss Account'!D24 -> 2771.94
A4: Total assets | B4: ='Balance Sheet'!B11+'Balance Sheet'!B12+'Balance Sheet'!B13+'Balance Sheet'!B14+'Balance Sheet'!B15+'Balance Sheet'!B18 -> 63308.29 | C4: ='Balance Sheet'!C11+'Balance Sheet'!C12+'Balance Sheet'!C13+'Balance Sheet'!C14+'Balance Sheet'!C15+'Balance Sheet'!C18 -> 69020.26 | D4: ='Balance Sheet'!D11+'Balance Sheet'!D12+'Balance Sheet'!D13+'Balance Sheet'!D14+'Balance Sheet'!D15+'Balance Sheet'!D18 -> 76110.94
A5: Operating cash flow | B5: ='Cash Flow Summary'!B4 -> 2406.7742 | C5: ='Cash Flow Summary'!C4 -> 1147.3 | D5: ='Cash Flow Summary'!D4 -> 2621.97
A6: Borrowings | B6: ='Balance Sheet'!B9 -> 35 | C6: ='Balance Sheet'!C9 -> 0 | D6: ='Balance Sheet'!D9 -> 0
A7: Share capital | B7: ='Balance Sheet'!B4 -> 492.69 | C7: ='Balance Sheet'!C4 -> 495.73 | D7: ='Balance Sheet'!D4 -> 498.49
A8: GDPI | B8: ='Ratio Analysis'!B7 -> 24776 | C8: ='Ratio Analysis'!C7 -> 26833 | D8: ='Ratio Analysis'!D7 -> 28712
A9: Average total assets | B9: =AVERAGE(B18,B4) -> 59197.247 | C9: =AVERAGE(B4:C4) -> 66164.275 | D9: =AVERAGE(C4:D4) -> 72565.6
A10: ROA (PAT / average assets) | B10: =B3/B9 -> 0.032410122 | C10: =C3/C9 -> 0.037910035 | D10: =D3/D9 -> 0.038199092
A11: Operating cash flow > 0 | C11: 1 | D11: 1
A12: CFO > PAT | C12: 0 | D12: 0
A13: Leverage measure: borrowings / total assets | B13: =B6/B4 -> 0.00055285019 | C13: =C6/C4 -> 0 | D13: =D6/D4 -> 0
A14: GDPI / average total assets | B14: =B8/B9 -> 0.41853297 | C14: =C8/C9 -> 0.40555118 | D14: =D8/D9 -> 0.39566957
A15: Share capital change | B15: — | C15: =C7-B7 -> 3.04 | D15: =D7-C7 -> 2.76
A16: ROA change | B16: — | C16: =C10-B10 -> 0.0054999134 | D16: =D10-C10 -> 0.00028905629
A18: Total assets FY2023 (opening; for FY2024 averages) | B18: 55086.204
A21: Criterion | B21: FY2025 point | C21: FY2026 point
A22: 1. Positive ROA | B22: =IF(C10>0,1,0) -> 1 | C22: =IF(D10>0,1,0) -> 1
A23: 2. Positive operating cash flow | B23: =IF(C5>0,1,0) -> 1 | C23: =IF(D5>0,1,0) -> 1
A24: 3. Improving ROA | B24: =IF(C10>B10,1,0) -> 1 | C24: =IF(D10>C10,1,0) -> 1
A25: 4. CFO exceeds net income | B25: =IF(C5>C3,1,0) -> 0 | C25: =IF(D5>D3,1,0) -> 0
A26: 5. Decreasing leverage (adapted) | B26: =IF(C13<=B13,1,0) -> 1 | C26: =IF(D13<=C13,1,0) -> 1
A27: 6. Improving current ratio | B27: N/A | C27: N/A
A28: 7. No equity dilution | B28: =IF(C7>B7,0,1) -> 0 | C28: =IF(D7>C7,0,1) -> 0
A29: 8. Improving gross margin | B29: N/A | C29: N/A
A30: 9. Improving asset turnover | B30: =IF(C14>B14,1,0) -> 0 | C30: =IF(D14>C14,1,0) -> 0
A31: Piotroski F-Score (out of 9) | B31: =SUM(B22:B30) -> 4 | C31: =SUM(C22:C30) -> 4
A32: Interpretation | B32: =IF(B34>=8/9,"Strong",IF(B34>=6/9,"Average to Good",IF(B34>=3/9,"Weak, Investigate","Poor, High Risk"))) -> Poor, High Risk | C32: =IF(C34>=8/9,"Strong",IF(C34>=6/9,"Average to Good",IF(C34>=3/9,"Weak, Investigate","Poor, High Risk"))) -> Poor, High Risk
A36: 8-9 Strong
A37: 6-7 Average to Good
A38: 3-5 Weak, Investigate
A39: 0-2 Poor, High Risk

Sheet __OpenSolverCache__

Sheet __OpenSolver__
A1: ModelSheet='Portfolio Analysis'!A:V
A2: OpenSolver_AdjNum=1
A3: OpenSolver_ChosenSolver=Google
A4: OpenSolver_FastBuild=0
A5: OpenSolver_LinearityCheck=1
A6: solver_adj='Portfolio Analysis'!B42:B44
A7: solver_lhs1='Portfolio Analysis'!B45
A8: solver_neg=1
A9: solver_num=1
A10: solver_opt='Portfolio Analysis'!G44
A11: solver_rel1=2
A12: solver_rhs1='Portfolio Analysis'!K15
... A15: solver_val=0
